Workbook

Sheet Menu
A1: Sourcing Analysis with AI

Sheet Executive Summary
A1: Executive Summary
B5: Total candidates | E5: Overall hiring rate | H5: Largest Bottleneck
B6: =GETPIVOTDATA("candidate_id",tables!$A$1) -> 601 | E6: =tables!K10 -> 0.081530782 | H6: =Analysis!C16 -> 0.30845771
B9: Across 4 roles | E9: 49 hires | H9: Teste taken > offer
B12: Best Source | E12: Top Recruiter Rate | H12: Reject Reason
B13: =Analysis!C62 -> Github | E13: =Analysis!E80 -> 0.15306122 | H13: =Analysis!E131 -> No response
B16: 11% hiring rate | E16: Bruno | H16: 210 candidates
A19: Key Insights

Sheet Analysis
A1: Analysis
A4: Funnel
A9: Overall
A10: Stage | B10: Candidates | C10: Conversion
A11: Sourced | B11: 601
A12: Response | B12: 408 | C12: =B12/B11 -> 0.67886855
A13: Screening Pass | B13: 308 | C13: =B13/B12 -> 0.75490196
A14: Interview Pass | B14: 234 | C14: =B14/B13 -> 0.75974026
A15: Test Taken | B15: 201 | C15: =B15/B14 -> 0.85897436
A16: Offer | B16: 62 | C16: =B16/B15 -> 0.30845771
A17: Hired | B17: 49 | C17: =B17/B16 -> 0.79032258
A22: Key Insight
A23: Only 31% of candidates who take the technical test receive an offer. This is the largest drop in the overall funnel and should trigger a review of assessment calibration, pre-test qualification, and final decision criteria.
A26: Funnel by role
A27: Analista de Dados | E27: Analista de Recrutamento
A28: Stage | B28: Candidates | C28: Conversion | E28: Stage | F28: Candidates | G28: Conversion
A29: Sourced | B29: 162 | E29: Sourced | F29: 147
A30: Response | B30: 118 | C30: =B30/B29 -> 0.72839506 | E30: Response | F30: 106 | G30: =F30/F29 -> 0.72108844
A31: Screening Pass | B31: 94 | C31: =B31/B30 -> 0.79661017 | E31: Screening Pass | F31: 82 | G31: =F31/F30 -> 0.77358491
A32: Interview Pass | B32: 70 | C32: =B32/B31 -> 0.74468085 | E32: Interview Pass | F32: 62 | G32: =F32/F31 -> 0.75609756
A33: Test Taken | B33: 63 | C33: =B33/B32 -> 0.9 | E33: Test Taken | F33: 49 | G33: =F33/F32 -> 0.79032258
A34: Offer | B34: 15 | C34: =B34/B33 -> 0.23809524 | E34: Offer | F34: 19 | G34: =F34/F33 -> 0.3877551
A35: Hired | B35: 11 | C35: =B35/B34 -> 0.73333333 | E35: Hired | F35: 17 | G35: =F35/F34 -> 0.89473684
A37: People BP | E37: Talent Acquisition Specialist
A38: Stage | B38: Candidates | C38: Conversion | E38: Stage | F38: Candidates | G38: Conversion
A39: Sourced | B39: 165 | E39: Sourced | F39: 127
A40: Response | B40: 105 | C40: =B40/B39 -> 0.63636364 | E40: Response | F40: 79 | G40: =F40/F39 -> 0.62204724
A41: Screening Pass | B41: 77 | C41: =B41/B40 -> 0.73333333 | E41: Screening Pass | F41: 55 | G41: =F41/F40 -> 0.69620253
A42: Interview Pass | B42: 59 | C42: =B42/B41 -> 0.76623377 | E42: Interview Pass | F42: 43 | G42: =F42/F41 -> 0.78181818
A43: Test Taken | B43: 49 | C43: =B43/B42 -> 0.83050847 | E43: Test Taken | F43: 40 | G43: =F43/F42 -> 0.93023256
A44: Offer | B44: 17 | C44: =B44/B43 -> 0.34693878 | E44: Offer | F44: 11 | G44: =F44/F43 -> 0.275
A45: Hired | B45: 14 | C45: =B45/B44 -> 0.82352941 | E45: Hired | F45: 7 | G45: =F45/F44 -> 0.63636364
A47: Role-Level Interpretation
A48: The Test → Offer stage is the main bottleneck for every role. Data Analyst has the lowest conversion at this point (23.8%), while Recruitment Analyst has the highest (38.8%). Talent Acquisition Specialist and People BP also show lower response rates at the top of the funnel, suggesting an additional opportunity to review candidate approach and role positioning.
A51: Source Channels
A52: Channel | B52: Hired NO | C52: Hired YES | D52: Total Geral | E52: Channel representative | F52: Channel hire conversation
C54: Channel | D54: No hired | E54: Hired | F54: Total | G54: Channel Representative | H54: Hire conversation
C55: Indicação | D55: 61 | E55: 3 | F55: 64 | G55: =F55/$F$63 -> 0.10648918 | H55: =E55/F55 -> 0.046875
C56: Evento | D56: 78 | E56: 4 | F56: 82 | G56: =F56/$F$63 -> 0.13643927 | H56: =E56/F56 -> 0.048780488
C57: Banco de Talentos | D57: 62 | E57: 6 | F57: 68 | G57: =F57/$F$63 -> 0.11314476 | H57: =E57/F57 -> 0.088235294
...

Sheet Recommendations
A1: Recomendations
A25: Conclusion

Sheet rawdata
A1: Recomendations
A4: candidate_id | B4: candidate_name | C4: candidate_email | D4: requisition_id | E4: role | F4: department | G4: location | H4: work_mode | I4: seniority | J4: years_experience | K4: hiring_manager | L4: recruiter | M4: source_channel | N4: decision_source | O4: sourced_date | P4: first_contact_date | Q4: response_received | R4: response_time_days | S4: screening_pass | T4: screening_date | U4: interview1_pass | V4: interview1_date | W4: test_taken | X4: test_date | Y4: technical_test_score | Z4: behavior_score | AA4: manager_score | AB4: offer_sent | AC4: offer_date | AD4: hired | AE4: hired_date | AF4: final_stage | AG4: rejection_reason | AH4: stage_duration_days | AI4: recruiter_notes
A5: 1 | B5: Sr. Erick da Mota | C5: bruna89@da.org | D5: REQ-1037 | E5: Analista de Recrutamento | F5: Tech | G5: Campinas | H5: Presencial | I5: Senior | J5: 5.6 | K5: Luiz Fernando | L5: Carla | M5: Hunting | N5: Hiring Manager | O5: 45718 | P5: 45722 | Q5: TRUE | R5: 10 | S5: TRUE | T5: 45729 | U5: TRUE | V5: 45733 | W5: TRUE | X5: 45739 | Y5: 83 | Z5: 66 | AA5: 75 | AB5: FALSE | AD5: FALSE | AF5: Test | AH5: 21 | AI5: Experiência sólida, mas expectativa salarial alta.
A6: 2 | B6: Camila da Mota | C6: rafaelmartins@gmail.com | D6: REQ-1025 | E6: Talent Acquisition Specialist | F6: Tech | G6: Campinas | H6: Presencial | I6: Pleno | J6: 3.6 | K6: Benício | L6: Ana | M6: Comunidade | N6: Hiring Manager | O6: 45801 | P6: 45806 | Q6: TRUE | R6: 1 | S6: FALSE | U6: FALSE | W6: FALSE | Y6: 62 | Z6: 89 | AA6: 75 | AB6: FALSE | AD6: FALSE | AF6: Sourced | AH6: 5 | AI6: Perfil técnico acima da média.
A7: 3 | B7: Stephany Ferreira | C7: levida-mota@gmail.com | D7: REQ-1015 | E7: Analista de Dados | F7: People | G7: Rio de Janeiro | H7: Remoto | I7: Pleno | J7: 3.4 | K7: Davi | L7: Fernanda | M7: Banco de Talentos | N7: Hiring Manager | O7: 45761 | P7: 45765 | Q7: TRUE | R7: 9 | S7: TRUE | T7: 45766 | U7: TRUE | V7: 45779 | W7: TRUE | X7: 45785 | Y7: 73 | Z7: 55 | AA7: 48 | AB7: FALSE | AD7: FALSE | AF7: Test | AG7: No response | AH7: 24 | AI7: Bom potencial de evolução.
A8: 4 | B8: Samuel Pires | C8: da-rosapietra@carvalho.com | D8: REQ-1038 | E8: Analista de Dados | F8: Data | G8: Remote | H8: Presencial | I8: Senior | J8: 9.9 | K8: Davi Lucca | L8: Carla | M8: Banco de Talentos | N8: Hiring Manager | O8: 45793 | P8: 45799 | Q8: FALSE | S8: FALSE | U8: FALSE | W8: FALSE | Y8: 91 | Z8: 91 | AA8: 84 | AB8: FALSE | AD8: FALSE | AF8: Rejected | AG8: No response | AH8: 6 | AI8: Pediu prazo adicional para retorno.
A9: 5 | B9: Ana Júlia Teixeira | C9: ana-luiza81@souza.com | D9: REQ-1085 | E9: Analista de Recrutamento | F9: People | G9: Remote | H9: Presencial | I9: Junior | J9: 2.5 | K9: Isabelly | L9: Ana | M9: Banco de Talentos | N9: Recruiter | O9: 45757 | P9: 45758 | Q9: FALSE | S9: FALSE | U9: FALSE | W9: FALSE | Y9: 89 | Z9: 81 | AA9: 84 | AB9: FALSE | AD9: FALSE | AF9: Rejected | AG9: No response | AH9: 1 | AI9: Perfil técnico acima da média.
A10: 6 | B10: Sophia Souza | C10: isabellaribeiro@cunha.br | D10: REQ-1073 | E10: Analista de Dados | F10: People | G10: Campinas | H10: Híbrido | I10: Senior | J10: 8.5 | K10: Sophia | L10: Bruno | M10: Indicação | N10: Tech Panel | O10: 45764 | P10: 45764 | Q10: FALSE | S10: FALSE | U10: FALSE | W10: FALSE | Y10: 81 | Z10: 88 | AA10: 91 | AB10: FALSE | AD10: FALSE | AF10: Rejected | AG10: No response | AH10: 0 | AI10: Feedback positivo do gestor.
A11: 7 | B11: Benjamin Sales | C11: sabrina61@santos.br | D11: REQ-1002 | E11: Analista de Recrutamento | F11: People | G11: Curitiba | H11: Presencial | I11: Pleno | J11: 4.5 | K11: Antônio | L11: Carla | M11: Banco de Talentos | N11: Tech Panel | O11: 45685 | P11: 45686 | Q11: TRUE | R11: 10 | S11: TRUE | T11: 45693 | U11: TRUE | V11: 45698 | W11: TRUE | X11: 45705 | Y11: 69 | Z11: 65 | AA11: 73 | AB11: FALSE | AD11: FALSE | AF11: Test | AH11: 20 | AI11: Feedback positivo do gestor.
A12: 8 | B12: Lorena Castro | C12: emanuelly10@moraes.br | D12: REQ-1087 | E12: People BP | F12: Tech | G12: Rio de Janeiro | H12: Remoto | I12: Staff | J12: 9.2 | K12: Carlos Eduardo | L12: Ana | M12: Hunting | N12: Hiring Manager | O12: 45780 | P12: 45789 | Q12: TRUE | R12: 6 | S12: TRUE | T12: 45794 | U12: TRUE | V12: 45797 | W12: FALSE | Y12: 77 | Z12: 68 | AA12: 81 | AB12: FALSE | AD12: FALSE | AF12: Interview | AH12: 17 | AI12: Feedback positivo do gestor.
A13: 9 | B13: Benício Rocha | C13: alveslucca@rezende.br | D13: REQ-1079 | E13: People BP | F13: People | G13: Campinas | H13: Remoto | I13: Senior | J13: 5.4 | K13: Isabelly | L13: Bruno | M13: Indicação | N13: Hiring Manager | O13: 45672 | P13: 45672 | Q13: TRUE | R13: 11 | S13: FALSE | U13: FALSE | W13: FALSE | Y13: 94 | Z13: 87 | AA13: 100 | AB13: FALSE | AD13: FALSE | AF13: Sourced | AH13: 0 | AI13: Experiência sólida, mas expectativa salarial alta.
A14: 10 | B14: Daniel Duarte | C14: sophiacarvalho@hotmail.com | D14: REQ-1079 | E14: Analista de Dados | F14: Operations | G14: São Paulo | H14: Remoto | I14: Pleno | J14: 6.4 | K14: Bruna | L14: Gustavo | M14: Evento | N14: TA Lead | O14: 45659 | P14: 45665 | Q14: TRUE | R14: 6 | S14: FALSE | U14: FALSE | W14: FALSE | Y14: 77 | Z14: 54 | AA14: 61 | AB14: FALSE | AD14: FALSE | AF14: Sourced | AG14: Salary mismatch | AH14: 6 | AI14: Boa comunicação e resposta rápida.
A15: 11 | B15: Antônio Barros | C15: fpeixoto@cavalcanti.br | D15: REQ-1069 | E15: People BP | F15: Operations | G15: Remote | H15: Presencial | I15: Senior | J15: 8 | K15: Isaac | L15: Bruno | M15: LinkedIn | N15: TA Lead | O15: 45669 | P15: 45672 | Q15: TRUE | R15: 11 | S15: TRUE | T15: 45680 | U15: TRUE | V15: 45691 | W15: TRUE | X15: 45698 | Y15: 61 | Z15: 78 | AA15: 71 | AB15: FALSE | AD15: FALSE | AF15: Test | AG15: Failed technical test | AH15: 29 | AI15: Pediu prazo adicional para retorno.
A16: 12 | B16: Evelyn Viana | C16: ana-vitoria30@bol.com.br | D16: REQ-1082 | E16: Talent Acquisition Specialist | F16: People | G16: Campinas | H16: Remoto | I16: Senior | J16: 6.2 | K16: Laís | L16: Gustavo | M16: Inbound | N16: Recruiter | O16: 45736 | P16: 45736 | Q16: FALSE | S16: FALSE | U16: FALSE | W16: FALSE | Y16: 67 | Z16: 66 | AA16: 70 | AB16: FALSE | AD16: FALSE | AF16: Rejected | AG16: No response | AH16: 0 | AI16: Experiência sólida, mas expectativa salarial alta.
A17: 13 | B17: Arthur Aragão | C17: carvalhomarcela@silva.com | D17: REQ-1067 | E17: Analista de Recrutamento | F17: Tech | G17: Rio de Janeiro | H17: Híbrido | I17: Senior | J17: 8.7 | K17: Carolina | L17: Carla | M17: Hunting | N17: Tech Panel | O17: 45784 | P17: 45787 | Q17: TRUE | R17: 1 | S17: TRUE | T17: 45794 | U17: TRUE | V17: 45808 | W17: TRUE | X17: 45810 | Y17: 76 | Z17: 78 | AA17: 74 | AB17: TRUE | AC17: 45816 | AD17: TRUE | AE17: 45824 | AF17: Hired | AH17: 40 | AI17: Pontos fortes em execução e autonomia.
A18: 14 | B18: Bárbara Cavalcanti | C18: ana78@ig.com.br | D18: REQ-1054 | E18: Talent Acquisition Specialist | F18: Tech | G18: Belo Horizonte | H18: Remoto | I18: Pleno | J18: 6 | K18: Stella | L18: Diego | M18: Banco de Talentos | N18: Hiring Manager | O18: 45724 | P18: 45729 | Q18: FALSE | S18: FALSE | U18: FALSE | W18: FALSE | Y18: 77 | Z18: 54 | AA18: 70 | AB18: FALSE | AD18: FALSE | AF18: Rejected | AG18: No response | AH18: 5 | AI18: Pediu prazo adicional para retorno.
A19: 15 | B19: Caroline Pereira | C19: davi85@yahoo.com.br | D19: REQ-1014 | E19: Talent Acquisition Specialist | F19: Operations | G19: Rio de Janeiro | H19: Remoto | I19: Senior | J19: 7 | K19: Sofia | L19: Fernanda | M19: Github | N19: Tech Panel | O19: 45772 | P19: 45775 | Q19: FALSE | S19: FALSE | U19: FALSE | W19: FALSE | Y19: 78 | Z19: 79 | AA19: 72 | AB19: FALSE | AD19: FALSE | AF19: Rejected | AG19: No response | AH19: 3 | AI19: Perfil técnico acima da média.
A20: 16 | B20: João Lucas Rocha | C20: yfernandes@ig.com.br | D20: REQ-1012 | E20: People BP | F20: Data | G20: Remote | H20: Remoto | I20: Junior | J20: 1.2 | K20: João Pedro | L20: Bruno | M20: Indicação | N20: Hiring Manager | O20: 45788 | P20: 45788 | Q20: TRUE | R20: 9 | S20: TRUE | T20: 45790 | U20: FALSE | W20: FALSE | Y20: 66 | Z20: 56 | AA20: 61 | AB20: FALSE | AD20: FALSE | AF20: Screening | AG20: Low technical fit | AH20: 2 | AI20: Boa comunicação e resposta rápida.
A21: 17 | B21: Dra. Gabriela Cardoso | C21: da-conceicaoguilherme@yahoo.com.br | D21: REQ-1024 | E21: Talent Acquisition Specialist | F21: Data | G21: Rio de Janeiro | H21: Presencial | I21: Pleno | J21: 2.7 | K21: Helena | L21: Gustavo | M21: Hunting | N21: Recruiter | O21: 45807 | P21: 45810 | Q21: FALSE | S21: FALSE | U21: FALSE | W21: FALSE | Y21: 66 | Z21: 58 | AA21: 66 | AB21: FALSE | AD21: FALSE | AF21: Rejected | AG21: No response | AH21: 3 | AI21: Apresentou aderência forte ao contexto da vaga.
A22: 18 | B22: Srta. Clara Caldeira | C22: costelamarcelo@mendes.br | D22: REQ-1068 | E22: People BP | F22: Operations | G22: Rio de Janeiro | H22: Remoto | I22: Junior | J22: 0 | K22: Stephany | L22: Fernanda | M22: Inbound | N22: TA Lead | O22: 45680 | P22: 45680 | Q22: TRUE | R22: 10 | S22: TRUE | T22: 45682 | U22: TRUE | V22: 45689 | W22: TRUE | X22: 45692 | Y22: 66 | Z22: 60 | AA22: 65 | AB22: FALSE | AD22: FALSE | AF22: Test | AG22: No response | AH22: 12 | AI22: Perfil técnico acima da média.
A23: 19 | B23: Sra. Ana Júlia Moreira | C23: barrosana-sophia@ig.com.br | D23: REQ-1094 | E23: People BP | F23: Operations | G23: Rio de Janeiro | H23: Híbrido | I23: Staff | J23: 9.2 | K23: Davi | L23: Bruno | M23: Comunidade | N23: TA Lead | O23: 45665 | P23: 45672 | Q23: TRUE | R23: 8 | S23: TRUE | T23: 45679 | U23: FALSE | W23: FALSE | Y23: 80 | Z23: 77 | AA23: 91 | AB23: FALSE | AD23: FALSE | AF23: Screening | AH23: 14 | AI23: Baixa responsividade nas etapas iniciais.
A24: 20 | B24: Juliana Teixeira | C24: halmeida@nascimento.com | D24: REQ-1082 | E24: People BP | F24: Operations | G24: Campinas | H24: Presencial | I24: Staff | J24: 7.7 | K24: Heitor | L24: Gustavo | M24: Inbound | N24: Tech Panel | O24: 45743 | P24: 45743 | Q24: TRUE | R24: 6 | S24: TRUE | T24: 45751 | U24: TRUE | V24: 45757 | W24: TRUE | X24: 45766 | Y24: 80 | Z24: 81 | AA24: 78 | AB24: TRUE | AC24: 45770 | AD24: TRUE | AE24: 45779 | AF24: Hired | AH24: 36 | AI24: Perfil técnico acima da média.
A25: 21 | B25: Emanuella Fernandes | C25: camposbryan@silva.com | D25: REQ-1023 | E25: Talent Acquisition Specialist | F25: People | G25: Campinas | H25: Híbrido | I25: Staff | J25: 11.2 | K25: Stephany | L25: Diego | M25: Github | N25: Tech Panel | O25: 45801 | P25: 45804 | Q25: FALSE | S25: FALSE | U25: FALSE | W25: FALSE | Y25: 79 | Z25: 57 | AA25: 76 | AB25: FALSE | AD25: FALSE | AF25: Rejected | AG25: No response | AH25: 3 | AI25: Pontos fortes em execução e autonomia.
A26: 22 | B26: Sra. Cecília Viana | C26: brenda33@uol.com.br | D26: REQ-1092 | E26: People BP | F26: Operations | G26: Belo Horizonte | H26: Híbrido | I26: Pleno | J26: 6 | K26: João Gabriel | L26: Ana | M26: Indicação | N26: Hiring Manager | O26: 45745 | P26: 45747 | Q26: TRUE | R26: 12 | S26: TRUE | T26: 45754 | U26: TRUE | V26: 45759 | W26: TRUE | X26: 45766 | Y26: 78 | Z26: 64 | AA26: 57 | AB26: FALSE | AD26: FALSE | AF26: Test | AG26: Accepted another offer | AH26: 21 | AI26: Apresentou aderência forte ao contexto da vaga.
A27: 23 | B27: Maria Fernanda Nogueira | C27: ncastro@melo.br | D27: REQ-1031 | E27: People BP | F27: Operations | G27: Campinas | H27: Híbrido | I27: Senior | J27: 5.3 | K27: Isabelly | L27: Carla | M27: Github | N27: Recruiter | O27: 45684 | P27: 45684 | Q27: TRUE | R27: 12 | S27: TRUE | T27: 45692 | U27: TRUE | V27: 45706 | W27: TRUE | X27: 45708 | Y27: 73 | Z27: 81 | AA27: 76 | AB27: TRUE | AC27: 45714 | AD27: TRUE | AE27: 45720 | AF27: Hired | AH27: 36 | AI27: Pediu prazo adicional para retorno.
A28: 24 | B28: Caroline Santos | C28: luiz-gustavomoraes@hotmail.com | D28: REQ-1025 | E28: Talent Acquisition Specialist | F28: Data | G28: Remote | H28: Presencial | I28: Pleno | J28: 5.3 | K28: Luna | L28: Gustavo | M28: Evento | N28: Tech Panel | O28: 45711 | P28: 45714 | Q28: FALSE | S28: FALSE | U28: FALSE | W28: FALSE | Y28: 73 | Z28: 82 | AA28: 84 | AB28: FALSE | AD28: FALSE | AF28: Rejected | AG28: No response | AH28: 3 | AI28: Pontos fortes em execução e autonomia.
A29: 25 | B29: Sr. Francisco Souza | C29: otavio73@ig.com.br | D29: REQ-1068 | E29: Analista de Recrutamento | F29: Operations | G29: Belo Horizonte | H29: Presencial | I29: Senior | J29: 7.6 | K29: Ian | L29: Fernanda | M29: Indicação | N29: Tech Panel | O29: 45726 | P29: 45728 | Q29: TRUE | R29: 2 | S29: FALSE | U29: FALSE | W29: FALSE | Y29: 83 | Z29: 98 | AA29: 94 | AB29: FALSE | AD29: FALSE | AF29: Sourced | AG29: Accepted another offer | AH29: 2 | AI29: Feedback positivo do gestor.
A30: 26 | B30: Maria Sophia Campos | C30: joao-felipe04@bol.com.br | D30: REQ-1012 | E30: Analista de Dados | F30: Tech | G30: Rio de Janeiro | H30: Remoto | I30: Junior | J30: 0.4 | K30: Diogo | L30: Gustavo | M30: LinkedIn | N30: Hiring Manager | O30: 45735 | P30: 45739 | Q30: FALSE | S30: FALSE | U30: FALSE | W30: FALSE | Y30: 63 | Z30: 72 | AA30: 76 | AB30: FALSE | AD30: FALSE | AF30: Rejected | AG30: No response | AH30: 4 | AI30: Perfil técnico acima da média.
A31: 27 | B31: Manuela Souza | C31: rcavalcanti@uol.com.br | D31: REQ-1083 | E31: People BP | F31: Operations | G31: Rio de Janeiro | H31: Remoto | I31: Junior | J31: 1.7 | K31: Ana Beatriz | L31: Carla | M31: Evento | N31: TA Lead | O31: 45709 | P31: 45712 | Q31: FALSE | S31: FALSE | U31: FALSE | W31: FALSE | Y31: 66 | Z31: 68 | AA31: 63 | AB31: FALSE | AD31: FALSE | AF31: Rejected | AG31: No response | AH31: 3 | AI31: Experiência sólida, mas expectativa salarial alta.
A32: 28 | B32: Dr. Luigi Nascimento | C32: jnogueira@ferreira.com | D32: REQ-1090 | E32: Talent Acquisition Specialist | F32: Operations | G32: Campinas | H32: Remoto | I32: Senior | J32: 7.5 | K32: Evelyn | L32: Gustavo | M32: LinkedIn | N32: Tech Panel | O32: 45699 | P32: 45702 | Q32: FALSE | S32: FALSE | U32: FALSE | W32: FALSE | Y32: 75 | Z32: 66 | AA32: 70 | AB32: FALSE | AD32: FALSE | AF32: Rejected | AG32: No response | AH32: 3 | AI32: Bom potencial de evolução.
A33: 29 | B33: Gustavo Henrique Pires | C33: cardosoyago@yahoo.com.br | D33: REQ-1048 | E33: Analista de Dados | F33: People | G33: São Paulo | H33: Presencial | I33: Pleno | J33: 3.3 | K33: Juliana | L33: Fernanda | M33: Comunidade | N33: TA Lead | O33: 45660 | P33: 45661 | Q33: TRUE | R33: 5 | S33: TRUE | T33: 45662 | U33: FALSE | W33: FALSE | Y33: 40 | Z33: 70 | AA33: 43 | AB33: FALSE | AD33: FALSE | AF33: Screening | AH33: 2 | AI33: Bom potencial de evolução.
A34: 30 | B34: Emanuelly Correia | C34: gustavo17@ig.com.br | D34: REQ-1037 | E34: Analista de Dados | F34: People | G34: São Paulo | H34: Híbrido | I34: Junior | J34: 3.5 | K34: Vinicius | L34: Diego | M34: Inbound | N34: TA Lead | O34: 45709 | P34: 45709 | Q34: TRUE | R34: 12 | S34: TRUE | T34: 45710 | U34: FALSE | W34: FALSE | Y34: 76 | Z34: 71 | AA34: 65 | AB34: FALSE | AD34: FALSE | AF34: Screening | AH34: 1 | AI34: Apresentou aderência forte ao contexto da vaga.
A35: 31 | B35: Benjamin Sales | C35: theo14@hotmail.com | D35: REQ-1070 | E35: Talent Acquisition Specialist | F35: Data | G35: Campinas | H35: Remoto | I35: Junior | J35: 3.9 | K35: Gustavo Henrique | L35: Bruno | M35: Evento | N35: Tech Panel | O35: 45786 | P35: 45790 | Q35: TRUE | R35: 6 | S35: TRUE | T35: 45799 | U35: FALSE | W35: FALSE | Y35: 71 | Z35: 82 | AA35: 86 | AB35: FALSE | AD35: FALSE | AF35: Screening | AG35: Low engagement | AH35: 13 | AI35: Boa comunicação e resposta rápida.
A36: 32 | B36: Dr. Samuel Araújo | C36: silvaluana@uol.com.br | D36: REQ-1079 | E36: Talent Acquisition Specialist | F36: People | G36: Remote | H36: Remoto | I36: Junior | J36: 4.9 | K36: João Felipe | L36: Bruno | M36: Inbound | N36: Tech Panel | O36: 45783 | P36: 45787 | Q36: TRUE | R36: 1 | S36: TRUE | T36: 45790 | U36: TRUE | V36: 45799 | W36: TRUE | X36: 45801 | Y36: 57 | Z36: 74 | AA36: 66 | AB36: FALSE | AD36: FALSE | AF36: Test | AH36: 18 | AI36: Experiência sólida, mas expectativa salarial alta.
A37: 33 | B37: Thiago Azevedo | C37: pereiraaugusto@gmail.com | D37: REQ-1045 | E37: Analista de Dados | F37: Tech | G37: Campinas | H37: Híbrido | I37: Junior | J37: 0.8 | K37: Lucas Gabriel | L37: Ana | M37: Evento | N37: TA Lead | O37: 45765 | P37: 45765 | Q37: FALSE | S37: FALSE | U37: FALSE | W37: FALSE | Y37: 60 | Z37: 84 | AA37: 66 | AB37: FALSE | AD37: FALSE | AF37: Rejected | AG37: No response | AH37: 0 | AI37: Demonstrou interesse claro na oportunidade.
A38: 34 | B38: Thiago Moraes | C38: zfreitas@bol.com.br | D38: REQ-1040 | E38: Analista de Recrutamento | F38: People | G38: Rio de Janeiro | H38: Presencial | I38: Junior | J38: 0 | K38: Benício | L38: Gustavo | M38: Github | N38: Hiring Manager | O38: 45776 | P38: 45776 | Q38: TRUE | R38: 3 | S38: TRUE | T38: 45779 | U38: TRUE | V38: 45783 | W38: TRUE | X38: 45792 | Y38: 75 | Z38: 87 | AA38: 92 | AB38: TRUE | AC38: 45796 | AD38: TRUE | AE38: 45805 | AF38: Hired | AH38: 29 | AI38: Baixa responsividade nas etapas iniciais.
A39: 35 | B39: Luiz Gustavo Moreira | C39: da-cunhajoao-gabriel@freitas.com | D39: REQ-1006 | E39: Analista de Recrutamento | F39: Tech | G39: Rio de Janeiro | H39: Híbrido | I39: Senior | J39: 6.2 | K39: Davi Lucas | L39: Bruno | M39: Hunting | N39: Tech Panel | O39: 45752 | P39: 45757 | Q39: FALSE | S39: FALSE | U39: FALSE | W39: FALSE | Y39: 98 | Z39: 90 | AA39: 84 | AB39: FALSE | AD39: FALSE | AF39: Rejected | AG39: No response | AH39: 5 | AI39: Boa comunicação e resposta rápida.
A40: 36 | B40: Maria Alice Carvalho | C40: luiza77@correia.br | D40: REQ-1007 | E40: People BP | F40: People | G40: Rio de Janeiro | H40: Remoto | I40: Pleno | J40: 3.5 | K40: Olivia | L40: Diego | M40: Inbound | N40: Recruiter | O40: 45669 | P40: 45669 | Q40: TRUE | R40: 8 | S40: FALSE | U40: FALSE | W40: FALSE | Y40: 55 | Z40: 92 | AA40: 79 | AB40: FALSE | AD40: FALSE | AF40: Sourced | AG40: Accepted another offer | AH40: 0 | AI40: Feedback positivo do gestor.
A41: 37 | B41: Rebeca Oliveira | C41: mourajoaquim@gmail.com | D41: REQ-1071 | E41: Talent Acquisition Specialist | F41: People | G41: Rio de Janeiro | H41: Remoto | I41: Pleno | J41: 5.3 | K41: Nicole | L41: Ana | M41: Comunidade | N41: Tech Panel | O41: 45777 | P41: 45777 | Q41: TRUE | R41: 11 | S41: TRUE | T41: 45786 | U41: FALSE | W41: FALSE | Y41: 45 | Z41: 75 | AA41: 45 | AB41: FALSE | AD41: FALSE | AF41: Screening | AH41: 9 | AI41: Feedback positivo do gestor.
A42: 38 | B42: Daniela Gomes | C42: rafael75@ig.com.br | D42: REQ-1068 | E42: Talent Acquisition Specialist | F42: Data | G42: Curitiba | H42: Remoto | I42: Pleno | J42: 5.3 | K42: Luiza | L42: Bruno | M42: Banco de Talentos | N42: Recruiter | O42: 45792 | P42: 45792 | Q42: TRUE | R42: 4 | S42: FALSE | U42: FALSE | W42: FALSE | Y42: 72 | Z42: 65 | AA42: 59 | AB42: FALSE | AD42: FALSE | AF42: Sourced | AG42: Culture add mismatch | AH42: 0 | AI42: Demonstrou interesse claro na oportunidade.
...

Sheet tables
A1: Rótulos de Linha | B1: Contagem de candidate_id | D1: Contagem de candidate_id | E1: Rótulos de Coluna | I1: Contagem de candidate_id | J1: Rótulos de Coluna | N1: Rótulos de Linha | O1: Contagem de candidate_id
A2: Talent Acquisition Specialist | B2: 127 | D2: Rótulos de Linha | E2: FALSO | F2: VERDADEIRO | G2: Total Geral | I2: Rótulos de Linha | J2: FALSO | K2: VERDADEIRO | L2: Total Geral | N2: FALSO | O2: 552
A3: Analista de Recrutamento | B3: 147 | D3: Indicação | E3: 61 | F3: 3 | G3: 64 | I3: Ana | J3: 65 | K3: 10 | L3: 75 | N3: Culture add mismatch | O3: 12
A4: Analista de Dados | B4: 162 | D4: Evento | E4: 78 | F4: 4 | G4: 82 | I4: Bruno | J4: 83 | K4: 15 | L4: 98 | N4: Accepted another offer | O4: 18
A5: People BP | B5: 165 | D5: Banco de Talentos | E5: 62 | F5: 6 | G5: 68 | I5: Carla | J5: 92 | K5: 9 | L5: 101 | N5: Salary mismatch | O5: 18
A6: Total Geral | B6: 601 | D6: Hunting | E6: 68 | F6: 7 | G6: 75 | I6: Diego | J6: 98 | K6: 5 | L6: 103 | N6: Headcount closed | O6: 22
D7: Inbound | E7: 62 | F7: 7 | G7: 69 | I7: Fernanda | J7: 99 | K7: 4 | L7: 103 | N7: Low engagement | O7: 23
D8: LinkedIn | E8: 74 | F8: 7 | G8: 81 | I8: Gustavo | J8: 115 | K8: 6 | L8: 121 | N8: Low technical fit | O8: 23
D9: Comunidade | E9: 82 | F9: 7 | G9: 89 | I9: Total Geral | J9: 552 | K9: 49 | L9: 601 | N9: Timing mismatch | O9: 24
D10: Github | E10: 65 | F10: 8 | G10: 73 | K10: =GETPIVOTDATA("candidate_id",$I$1,"hired",TRUE)/GETPIVOTDATA("candidate_id",$I$1) -> 0.081530782 | N10: Failed technical test | O10: 25
D11: Total Geral | E11: 552 | F11: 49 | G11: 601 | N11: (vazio) | O11: 177
N12: No response | O12: 210
N13: VERDADEIRO | O13: 49
N14: (vazio) | O14: 49
N15: Total Geral | O15: 601
